Workbook

Sheet Detail1-Nguyễn Ngọc Tân-G008@gd
A1: # | B1: Full Name | C1: User name | D1: Team ID | E1: Ngày | F1: UID | G1: Task Link | H1: Status | I1: Feedback (optional) | J1: # checklist | K1: decision | L1: trace_id
A2: 1 | B2: Nguyễn Ngọc Tân | C2: G008@gdsonline.tech | D2: SN02 | E2: 29/12 | F2: d92f8aef-fe99-4941-9929-b67c99c3cb02 | G2: https://webolmo-data-snorkel.allen.ai/20251219_snorkel_batch010__llm_navqa_popular_websites__98 | H2: Submission | K2: ACCEPT | L2: 20251219_snorkel_batch010__llm_navqa_popular_websites__98
A3: 1 | B3: Nguyễn Ngọc Tân | C3: G008@gdsonline.tech | D3: SN02 | E3: 29/12 | F3: 65d83709-fd59-4c32-bf89-a41e329ca499 | G3: https://webolmo-data-snorkel.allen.ai/20251219_snorkel_batch006__llm_navqa_onlinemind2web_websites__103 | H3: Submission | K3: ACCEPT | L3: 20251219_snorkel_batch006__llm_navqa_onlinemind2web_websites__103
A4: 1 | B4: Nguyễn Ngọc Tân | C4: G008@gdsonline.tech | D4: SN02 | E4: 29/12 | F4: 60f081c5-75f9-4d2f-b086-06d47b46e1a8 | G4: https://webolmo-data-snorkel.allen.ai/20251219_snorkel_batch009__llm_navqa_popular_websites__127 | H4: Submission | K4: ACCEPT | L4: 20251219_snorkel_batch009__llm_navqa_popular_websites__127
A5: 1 | B5: Nguyễn Ngọc Tân | C5: G008@gdsonline.tech | D5: SN02 | E5: 30/12 | F5: 091a355d-3828-4238-b9fb-71198f49eb5f | G5: https://webolmo-data-snorkel.allen.ai/20251219_snorkel_batch002__llm_navqa_webvoyager_websites__76 | H5: Submission | K5: ACCEPT | L5: 20251219_snorkel_batch002__llm_navqa_webvoyager_websites__76
A6: 1 | B6: Nguyễn Ngọc Tân | C6: G008@gdsonline.tech | D6: SN02 | E6: 30/12 | F6: 0c6a73a9-e58a-43bd-8d7c-f33e2138eb67 | G6: https://webolmo-data-snorkel.allen.ai/20251219_snorkel_batch003__llm_navqa_popular_websites__29 | H6: Submission | K6: ACCEPT | L6: 20251219_snorkel_batch003__llm_navqa_popular_websites__29
A7: 1 | B7: Nguyễn Ngọc Tân | C7: G008@gdsonline.tech | D7: SN02 | E7: 30/12 | F7: c6ca2943-db46-4ae3-bbc8-799015466b82 | G7: https://webolmo-data-snorkel.allen.ai/20251219_snorkel_batch006__llm_navqa_onlinemind2web_websites__25 | H7: Submission | I7: không tìm thấy sách yêu cầu | J7: 40 | K7: ACCEPT | L7: 20251219_snorkel_batch006__llm_navqa_onlinemind2web_websites__25
A8: 1 | B8: Nguyễn Ngọc Tân | C8: G008@gdsonline.tech | D8: SN02 | E8: 31/12 | F8: df409c1b-16f2-4319-9ad3-6688229d1821 | G8: https://webolmo-data-snorkel.allen.ai/20251121_snorkel_batch001__webvoyager_like__475 | H8: Submission | K8: ACCEPT | L8: 20251121_snorkel_batch001__webvoyager_like__475
A9: 1 | B9: Nguyễn Ngọc Tân | C9: G008@gdsonline.tech | D9: SN02 | E9: 31/12 | F9: d3b619c0-7751-461e-a0e7-5297a417377b | G9: https://webolmo-data-snorkel.allen.ai/20251219_snorkel_batch007__llm_navqa_webvoyager_websites__149 | H9: Submission | K9: ACCEPT | L9: 20251219_snorkel_batch007__llm_navqa_webvoyager_websites__149
A10: 1 | B10: Nguyễn Ngọc Tân | C10: G008@gdsonline.tech | D10: SN02 | E10: 46296 | F10: 6f2e4a6a-0fac-4b4c-8b8a-576a04c2e538 | G10: https://webolmo-data-snorkel.allen.ai/20251126_snorkel_batch011__llm_step_webvoyager_websites__0 | H10: Submission | K10: ACCEPT | L10: 20251126_snorkel_batch011__llm_step_webvoyager_websites__0
A11: 1 | B11: Nguyễn Ngọc Tân | C11: G008@gdsonline.tech | D11: SN02 | E11: 46296 | F11: 7a4462f8-19bb-4ea3-a14d-bd63c8d62191 | G11: https://webolmo-data-snorkel.allen.ai/20251126_snorkel_batch014__llm_step_popular_websites__6 | H11: Submission | K11: ACCEPT | L11: 20251126_snorkel_batch014__llm_step_popular_websites__6
A12: 1 | B12: Nguyễn Ngọc Tân | C12: G008@gdsonline.tech | D12: SN02 | E12: 46327 | F12: af046b40-3693-4e31-bf8d-77b752fec8d5 | G12: https://webolmo-data-snorkel.allen.ai/20251126_snorkel_batch012__llm_step_onlinemind2web_websites__39 | H12: Submission | K12: ACCEPT | L12: 20251126_snorkel_batch012__llm_step_onlinemind2web_websites__39
A13: 1 | B13: Nguyễn Ngọc Tân | C13: G008@gdsonline.tech | D13: SN02 | E13: 46357 | F13: 27e4ccb3-cdbb-4b45-8cbe-161395bf6af2 | G13: https://webolmo-data-snorkel.allen.ai/20251126_snorkel_batch011__llm_step_popular_websites__32 | H13: Submission | I13: không có kết quả tìm kiếm | K13: ACCEPT | L13: 20251126_snorkel_batch011__llm_step_popular_websites__32
A14: 1 | B14: Nguyễn Ngọc Tân | C14: G008@gdsonline.tech | D14: SN02 | E14: 46357 | F14: f42c83ac-fb69-47d9-a384-07d6c1bd5d6c | G14: https://webolmo-data-snorkel.allen.ai/20251126_snorkel_batch020__llm_step_popular_websites__100 | H14: Submission | I14: tìm thấy kết quả nhưng không có filter | K14: ACCEPT | L14: 20251126_snorkel_batch020__llm_step_popular_websites__100
A15: 1 | B15: Nguyễn Ngọc Tân | C15: G008@gdsonline.tech | D15: SN02 | E15: 46357 | F15: 280abf7f-3499-4dee-9040-a839788eb8e2 | G15: https://webolmo-data-snorkel.allen.ai/20251126_snorkel_batch012__llm_step_webvoyager_websites__9 | H15: Submission | K15: ACCEPT | L15: 20251126_snorkel_batch012__llm_step_webvoyager_websites__9
A16: 1 | B16: Nguyễn Ngọc Tân | C16: G008@gdsonline.tech | D16: SN02 | E16: 46357 | F16: 7f271ea1-a019-462a-9ec7-87b592b4090f | G16: https://webolmo-data-snorkel.allen.ai/20251126_snorkel_batch014__llm_step_webvoyager_websites__75 | H16: Submission | K16: ACCEPT | L16: 20251126_snorkel_batch014__llm_step_webvoyager_websites__75
A17: 1 | B17: Nguyễn Ngọc Tân | C17: G008@gdsonline.tech | D17: SN02 | E17: 46357 | F17: 06c08730-29ee-42d1-90cc-cbcd042777d1 | G17: https://webolmo-data-snorkel.allen.ai/20260107_snorkel_batch003_step_tasks__career_job_search__18 | H17: Submission | I17: không có bộ lọc | K17: ACCEPT | L17: 20260107_snorkel_batch003_step_tasks__career_job_search__18
A18: 1 | B18: Nguyễn Ngọc Tân | C18: G008@gdsonline.tech | D18: SN02 | E18: 46357 | F18: 3ee07b7e-3dbf-448b-9f78-86e4de6eb21e | G18: https://webolmo-data-snorkel.allen.ai/20251219_snorkel_batch008__llm_navqa_webvoyager_websites__24 | H18: Submission | K18: ACCEPT | L18: 20251219_snorkel_batch008__llm_navqa_webvoyager_websites__24
A19: 1 | B19: Nguyễn Ngọc Tân | C19: G008@gdsonline.tech | D19: SN02 | E19: 46357 | F19: fdc22f07-fcd8-417e-b37c-e121615b49d9 | G19: https://webolmo-data-snorkel.allen.ai/20260107_snorkel_batch001_step_tasks__general_news_nav__14 | H19: Submission | K19: ACCEPT | L19: 20260107_snorkel_batch001_step_tasks__general_news_nav__14
A20: 1 | B20: Nguyễn Ngọc Tân | C20: G008@gdsonline.tech | D20: SN02 | E20: 46357 | F20: 84d5e7c7-604e-4895-a571-3a401dbd2c04 | G20: https://webolmo-data-snorkel.allen.ai/20260107_snorkel_batch003_step_tasks__food_recipes__13 | H20: Submission | K20: ACCEPT | L20: 20260107_snorkel_batch003_step_tasks__food_recipes__13
A21: 1 | B21: Nguyễn Ngọc Tân | C21: G008@gdsonline.tech | D21: SN02 | E21: 46357 | F21: 9ebccd3b-aacc-40da-a325-d367bc81666b | G21: https://webolmo-data-snorkel.allen.ai/20260107_snorkel_batch003_step_tasks__shopping_search_and_add_to_cart__23 | H21: Submission | K21: ACCEPT | L21: 20260107_snorkel_batch003_step_tasks__shopping_search_and_add_to_cart__23
A22: 1 | B22: Nguyễn Ngọc Tân | C22: G008@gdsonline.tech | D22: SN02 | E22: 46357 | F22: f1f15dbe-9796-45f4-a8e4-1fbe562a555c | G22: https://webolmo-data-snorkel.allen.ai/20260107_snorkel_batch003_step_tasks__career_company_research__39 | H22: Submission | I22: không tìm thấy kết quả theo yêu cầu | K22: ACCEPT | L22: 20260107_snorkel_batch003_step_tasks__career_company_research__39
A23: 1 | B23: Nguyễn Ngọc Tân | C23: G008@gdsonline.tech | D23: SN02 | E23: 46357 | F23: 5e990f64-c0ce-411e-b950-4401618dcc85 | G23: https://webolmo-data-snorkel.allen.ai/20251126_snorkel_batch013__llm_step_onlinemind2web_websites__26 | H23: Submission | K23: ACCEPT | L23: 20251126_snorkel_batch013__llm_step_onlinemind2web_websites__26
A24: 1 | B24: Nguyễn Ngọc Tân | C24: G008@gdsonline.tech | D24: SN02 | E24: 46357 | F24: 6b3d31c2-c1c4-4c10-87a3-6e2b77ba89b3 | G24: https://webolmo-data-snorkel.allen.ai/20260107_snorkel_batch002_step_tasks__maps_route_planning__21 | H24: Submission | K24: ACCEPT | L24: 20260107_snorkel_batch002_step_tasks__maps_route_planning__21
A25: 1 | B25: Nguyễn Ngọc Tân | C25: G008@gdsonline.tech | D25: SN02 | E25: 46357 | F25: 48bab6a9-7701-443b-8cd8-6ee56c5896ac | G25: https://webolmo-data-snorkel.allen.ai/20260107_snorkel_batch002_step_tasks__maps_nearby__18 | H25: Submission | K25: ACCEPT | L25: 20260107_snorkel_batch002_step_tasks__maps_nearby__18
A26: 1 | B26: Nguyễn Ngọc Tân | C26: G008@gdsonline.tech | D26: SN02 | E26: 46357 | F26: 159d9367-b9ef-49fd-9a5c-a937f6dcd09b | G26: https://webolmo-data-snorkel.allen.ai/20260107_snorkel_batch001_step_tasks__general_news_nav__3 | H26: Submission | K26: ACCEPT | L26: 20260107_snorkel_batch001_step_tasks__general_news_nav__3
A27: 1 | B27: Nguyễn Ngọc Tân | C27: G008@gdsonline.tech | D27: SN02 | E27: 46357 | F27: dc41a5b5-7da5-4e1a-b301-d5bdad85d684 | G27: https://webolmo-data-snorkel.allen.ai/20260107_snorkel_batch001_step_tasks__general_news_nav__29 | H27: Submission | K27: ACCEPT | L27: 20260107_snorkel_batch001_step_tasks__general_news_nav__29
A28: 1 | B28: Nguyễn Ngọc Tân | C28: G008@gdsonline.tech | D28: SN02 | E28: 13/01 | F28: 708e6fd4-f563-46f0-98a2-e5f52d46aa16 | G28: https://webolmo-data-snorkel.allen.ai/20251126_snorkel_batch019__llm_step_popular_websites__86 | H28: Submission | I28: không có lọc danh mục theo yêu cầu | K28: ACCEPT | L28: 20251126_snorkel_batch019__llm_step_popular_websites__86
A29: 1 | B29: Nguyễn Ngọc Tân | C29: G008@gdsonline.tech | D29: SN02 | E29: 13/01 | F29: de8ab469-af67-4d1e-9a16-a942e61b316c | G29: https://webolmo-data-snorkel.allen.ai/20251126_snorkel_batch016__llm_step_popular_websites__152 | H29: Submission | I29: click vào kết quả mở tab mới | K29: ACCEPT | L29: 20251126_snorkel_batch016__llm_step_popular_websites__152
A30: 1 | B30: Nguyễn Ngọc Tân | C30: G008@gdsonline.tech | D30: SN02 | E30: 13/01 | F30: caf7b75d-a72d-4bee-bbd6-68e365e5d227 | G30: https://webolmo-data-snorkel.allen.ai/20260107_snorkel_batch003_step_tasks__car_rental_search__7 | H30: Submission | K30: ACCEPT | L30: 20260107_snorkel_batch003_step_tasks__car_rental_search__7
A31: 1 | B31: Nguyễn Ngọc Tân | C31: G008@gdsonline.tech | D31: SN02 | E31: 13/01 | F31: 33f5ef58-509f-4fbc-902c-10abbbd8854d | G31: https://webolmo-data-snorkel.allen.ai/20251210_snorkel_batch001__llm_step_onlinemind2web_websites__169 | H31: Submission | I31: mở tab mới khi click vào kết quả | K31: ACCEPT | L31: 20251210_snorkel_batch001__llm_step_onlinemind2web_websites__169
A32: 1 | B32: Nguyễn Ngọc Tân | C32: G008@gdsonline.tech | D32: SN02 | E32: 13/01 | F32: 41310ae1-6690-4837-a2d5-aa333606472c | G32: https://webolmo-data-snorkel.allen.ai/20260107_snorkel_batch002_step_tasks__maps_route_planning__34 | H32: Submission | K32: ACCEPT | L32: 20260107_snorkel_batch002_step_tasks__maps_route_planning__34
A33: 1 | B33: Nguyễn Ngọc Tân | C33: G008@gdsonline.tech | D33: SN02 | E33: 13/01 | F33: 1b5b5266-f4b1-4e20-812f-70eaa5e42c2e | G33: https://webolmo-data-snorkel.allen.ai/20260107_snorkel_batch001_step_tasks__maps_directions__4 | H33: Submission | K33: ACCEPT | L33: 20260107_snorkel_batch001_step_tasks__maps_directions__4
A34: 1 | B34: Nguyễn Ngọc Tân | C34: G008@gdsonline.tech | D34: SN02 | E34: 13/01 | F34: 061d3e1d-7e8d-421f-b5fc-1f52b744ed76 | G34: https://webolmo-data-snorkel.allen.ai/20260107_snorkel_batch002_step_tasks__maps_distance__12 | H34: Submission | K34: ACCEPT | L34: 20260107_snorkel_batch002_step_tasks__maps_distance__12
A35: 1 | B35: Nguyễn Ngọc Tân | C35: G008@gdsonline.tech | D35: SN02 | E35: 13/01 | F35: e06123de-8210-41d9-8f99-2d6fd6b5c042 | G35: https://webolmo-data-snorkel.allen.ai/20260107_snorkel_batch002_step_tasks__maps_distance__20 | H35: Submission | K35: ACCEPT | L35: 20260107_snorkel_batch002_step_tasks__maps_distance__20
A36: 1 | B36: Nguyễn Ngọc Tân | C36: G008@gdsonline.tech | D36: SN02 | E36: 13/01 | F36: 8f15136e-d714-42c9-b50c-496968c047f8 | G36: https://webolmo-data-snorkel.allen.ai/20260107_snorkel_batch002_step_tasks__maps_route_planning__9 | H36: Submission | K36: ACCEPT | L36: 20260107_snorkel_batch002_step_tasks__maps_route_planning__9
A37: 1 | B37: Nguyễn Ngọc Tân | C37: G008@gdsonline.tech | D37: SN02 | E37: 14/01 | F37: ed0db5df-8b88-4170-8e05-bd24822df7c6 | G37: https://webolmo-data-snorkel.allen.ai/20251126_snorkel_batch016__llm_step_onlinemind2web_websites__18 | H37: Submission | K37: ACCEPT | L37: 20251126_snorkel_batch016__llm_step_onlinemind2web_websites__18
A38: 1 | B38: Nguyễn Ngọc Tân | C38: G008@gdsonline.tech | D38: SN02 | E38: 15/01 | F38: 717a9e03-666c-4956-aff6-9c55a6130c95 | G38: https://webolmo-data-snorkel.allen.ai/20251210_snorkel_batch003__llm_step_webvoyager_websites__94 | H38: Submission | K38: ACCEPT | L38: 20251210_snorkel_batch003__llm_step_webvoyager_websites__94
A39: 1 | B39: Nguyễn Ngọc Tân | C39: G008@gdsonline.tech | D39: SN02 | E39: 15/01 | F39: e0689dac-6e1c-469a-aa23-c573262146cf | G39: https://webolmo-data-snorkel.allen.ai/20260113_snorkel_batch001_procedural__maps_visual_search__3 | H39: Submission | I39: không tìm thấy công viên gần nhất | K39: ACCEPT | L39: 20260113_snorkel_batch001_procedural__maps_visual_search__3
A40: 1 | B40: Nguyễn Ngọc Tân | C40: G008@gdsonline.tech | D40: SN02 | E40: 17/01 | F40: ccd32613-811a-475f-a41c-60e7f449df1c | G40: https://webolmo-data-snorkel.allen.ai/20260113_snorkel_batch006_procedural__maps_nearby__7 | H40: Submission | K40: ACCEPT | L40: 20260113_snorkel_batch006_procedural__maps_nearby__7
...

Sheet Performance Report
B4: TEAM | C4: SỐ ACC | D4: TỔNG TASK | E4: TRUNG BÌNH Task / acc / ngày | F4: SỐ NGÀY | G4: Tuần 1 | L4: Tuần 2 | S4: Tuần 3 | Z4: Tuần 4
G5: 24/12 | H5: 25/12 | I5: 26/12 | J5: 27/12 | K5: 28/12 | L5: 29/12 | M5: 30/12 | N5: 31/12 | O5: 46023 | P5: 46054 | Q5: 46082 | R5: 46113 | S5: 46143 | T5: 46174 | U5: 46204 | V5: 46235 | W5: 46266 | X5: 46296 | Y5: 46327 | Z5: 46357 | AA5: 13/01 | AB5: 14/01 | AC5: 15/01 | AD5: 16/01 | AE5: 17/01 | AF5: 18/01
B6: TỔNG | C6: =SUM(C7:C10) -> 18 | D6: =sum(G6:AK6) -> 559 | E6: =IFERROR(D6/C6/F6,"") -> 7.7638889 | F6: =countif(G6:N6,">0") -> 4 | G6: =SUM(G7:G10) -> 0 | H6: =SUM(H7:H10) -> 0 | I6: =SUM(I7:I10) -> 0 | J6: =SUM(J7:J10) -> 124 | K6: =SUM(K7:K10) -> 106 | L6: =SUM(L7:L10) -> 0 | M6: =SUM(M7:M10) -> 57 | N6: =SUM(N7:N10) -> 22 | ... AF6: =SUM(AF7:AF10) -> 7
B7: SN01 | C7: 7 | D7: =sum(G7:AK7) -> 0 | E7: =IFERROR(D7/C7/F7,"") | F7: =countif(G7:N7,">0") -> 0 | G7: =countifs('SN01'!$F$3:$F$2001,G$5,'SN01'!$G$3:$G$2001,"*") -> 0 | H7: =countifs('SN01'!$F$3:$F$2001,H$5,'SN01'!$G$3:$G$2001,"*") -> 0 | I7: =countifs('SN01'!$F$3:$F$2001,I$5,'SN01'!$G$3:$G$2001,"*") -> 0 | J7: =countifs('SN01'!$F$3:$F$2001,J$5,'SN01'!$G$3:$G$2001,"*") -> 0 | K7: =countifs('SN01'!$F$3:$F$2001,K$5,'SN01'!$G$3:$G$2001,"*") -> 0 | L7: =countifs('SN01'!$F$3:$F$2001,L$5,'SN01'!$G$3:$G$2001,"*") -> 0 | M7: =countifs('SN01'!$F$3:$F$2001,M$5,'SN01'!$G$3:$G$2001,"*") -> 0 | N7: =countifs('SN01'!$F$3:$F$2001,N$5,'SN01'!$G$3:$G$2001,"*") -> 0 | ... AF7: =countifs('SN01'!$F$3:$F$2001,AF$5,'SN01'!$G$3:$G$2001,"*") -> 0
B8: SN02 | C8: 7 | D8: =sum(G8:AK8) -> 559 | E8: =IFERROR(D8/C8/F8,"") -> 19.964286 | F8: =countif(G8:N8,">0") -> 4 | G8: =countifs('SN02'!$F$3:$F$781,G$5,'SN02'!$G$3:$G$781,"*") -> 0 | H8: =countifs('SN02'!$F$3:$F$781,H$5,'SN02'!$G$3:$G$781,"*") -> 0 | I8: =countifs('SN02'!$F$3:$F$781,I$5,'SN02'!$G$3:$G$781,"*") -> 0 | J8: =countifs('SN02'!$F$3:$F$781,J$5,'SN02'!$G$3:$G$781,"*") -> 124 | K8: =countifs('SN02'!$F$3:$F$781,K$5,'SN02'!$G$3:$G$781,"*") -> 106 | L8: =countifs('SN01'!$F$3:$F$2001,L$5,'SN01'!$G$3:$G$2001,"*") -> 0 | M8: =countifs('SN02'!$F$3:$F$781,M$5,'SN02'!$G$3:$G$781,"*") -> 57 | N8: =countifs('SN02'!$F$3:$F$781,N$5,'SN02'!$G$3:$G$781,"*") -> 22 | O8: =countifs('SN01'!$F$3:$F$2001,O$5,'SN01'!$G$3:$G$2001,"*") -> 0 | P8: =countifs('SN02'!$F$3:$F$781,P$5,'SN02'!$G$3:$G$781,"*") -> 0 | Q8: =countifs('SN02'!$F$3:$F$781,Q$5,'SN02'!$G$3:$G$781,"*") -> 0 | R8: =countifs('SN02'!$F$3:$F$781,R$5,'SN02'!$G$3:$G$781,"*") -> 0 | S8: =countifs('SN02'!$F$3:$F$781,S$5,'SN02'!$G$3:$G$781,"*") -> 0 | T8: =countifs('SN02'!$F$3:$F$781,T$5,'SN02'!$G$3:$G$781,"*") -> 0 | U8: =countifs('SN02'!$F$3:$F$781,U$5,'SN02'!$G$3:$G$781,"*") -> 0 | V8: =countifs('SN02'!$F$3:$F$781,V$5,'SN02'!$G$3:$G$781,"*") -> 1 | W8: =countifs('SN02'!$F$3:$F$781,W$5,'SN02'!$G$3:$G$781,"*") -> 0 | ... Y8: =countifs('SN02'!$F$3:$F$781,Y$5,'SN02'!$G$3:$G$781,"*") -> 85 | Z8: =countifs('SN01'!$F$3:$F$2001,Z$5,'SN01'!$G$3:$G$2001,"*") -> 0 | AA8: =countifs('SN02'!$F$3:$F$781,AA$5,'SN02'!$G$3:$G$781,"*") -> 96 | AB8: =countifs('SN02'!$F$3:$F$781,AB$5,'SN02'!$G$3:$G$781,"*") -> 40 | AC8: =countifs('SN01'!$F$3:$F$2001,AC$5,'SN01'!$G$3:$G$2001,"*") -> 0 | AD8: =countifs('SN02'!$F$3:$F$781,AD$5,'SN02'!$G$3:$G$781,"*") -> 2 | AE8: =countifs('SN02'!$F$3:$F$781,AE$5,'SN02'!$G$3:$G$781,"*") -> 9 | AF8: =countifs('SN02'!$F$3:$F$781,AF$5,'SN02'!$G$3:$G$781,"*") -> 7
B9: SN03 | C9: 1 | D9: =sum(G9:AK9) -> 0 | E9: =IFERROR(D9/C9/F9,"") | F9: =countif(G9:N9,">0") -> 0 | G9: =countifs('SN03'!$F$3:$F$2000,G$5,'SN03'!$G$3:$G$2000,"*") -> 0 | H9: =countifs('SN03'!$F$3:$F$2000,H$5,'SN03'!$G$3:$G$2000,"*") -> 0 | I9: =countifs('SN03'!$F$3:$F$2000,I$5,'SN03'!$G$3:$G$2000,"*") -> 0 | J9: =countifs('SN03'!$F$3:$F$2000,J$5,'SN03'!$G$3:$G$2000,"*") -> 0 | K9: =countifs('SN03'!$F$3:$F$2000,K$5,'SN03'!$G$3:$G$2000,"*") -> 0 | L9: =countifs('SN03'!$F$3:$F$2000,L$5,'SN03'!$G$3:$G$2000,"*") -> 0 | M9: =countifs('SN03'!$F$3:$F$2000,M$5,'SN03'!$G$3:$G$2000,"*") -> 0 | N9: =countifs('SN03'!$F$3:$F$2000,N$5,'SN03'!$G$3:$G$2000,"*") -> 0 | ... AF9: =countifs('SN03'!$F$3:$F$2000,AF$5,'SN03'!$G$3:$G$2000,"*") -> 0
B10: SN04 | C10: 3 | D10: =sum(G10:AK10) -> 0 | E10: =IFERROR(D10/C10/F10,"") | F10: =countif(G10:N10,">0") -> 0 | G10: =countifs('SN04'!$F$2:$F$7926,G$5,'SN04'!$G$2:$G$7926,"*") -> 0 | H10: =countifs('SN04'!$F$2:$F$7926,H$5,'SN04'!$G$2:$G$7926,"*") -> 0 | I10: =countifs('SN04'!$F$2:$F$7926,I$5,'SN04'!$G$2:$G$7926,"*") -> 0 | J10: =countifs('SN04'!$F$2:$F$7926,J$5,'SN04'!$G$2:$G$7926,"*") -> 0 | K10: =countifs('SN04'!$F$2:$F$7926,K$5,'SN04'!$G$2:$G$7926,"*") -> 0 | L10: =countifs('SN04'!$F$2:$F$7926,L$5,'SN04'!$G$2:$G$7926,"*") -> 0 | M10: =countifs('SN04'!$F$2:$F$7926,M$5,'SN04'!$G$2:$G$7926,"*") -> 0 | N10: =countifs('SN04'!$F$2:$F$7926,N$5,'SN04'!$G$2:$G$7926,"*") -> 0 | ... AF10: =countifs('SN04'!$F$2:$F$7926,AF$5,'SN04'!$G$2:$G$7926,"*") -> 0
B14: # | C14: Full Name | D14: Tổng task | E14: User name | F14: Team ID | G14: 24/12 | H14: 25/12 | I14: 26/12 | J14: 27/12 | K14: 28/12 | L14: 29/12 | M14: 30/12 | N14: 31/12 | O14: =O5 -> 46023 | P14: =P5 -> 46054 | Q14: =Q5 -> 46082 | R14: =R5 -> 46113 | S14: =S5 -> 46143 | T14: =T5 -> 46174 | U14: =U5 -> 46204 | V14: =V5 -> 46235 | ... AF14: =AF5 -> 18/01
B15: 1 | C15: Dương Xuân Hiếu | D15: =sum(H15:AK15) -> 0 | E15: G001@gdsonline.tech | F15: SN01 | G15: =countifs('SN01'!$F$3:$F$2001,G$5,'SN01'!$D$3:$D$2001,$E15,'SN01'!$G$3:$G$2001,"*") -> 0 | H15: =countifs('SN01'!$F$3:$F$2001,H$5,'SN01'!$D$3:$D$2001,$E15,'SN01'!$G$3:$G$2001,"*") -> 0 | I15: =countifs('SN01'!$F$3:$F$2001,I$5,'SN01'!$D$3:$D$2001,$E15,'SN01'!$G$3:$G$2001,"*") -> 0 | J15: =countifs('SN01'!$F$3:$F$2001,J$5,'SN01'!$D$3:$D$2001,$E15,'SN01'!$G$3:$G$2001,"*") -> 0 | K15: =countifs('SN01'!$F$3:$F$2001,K$5,'SN01'!$D$3:$D$2001,$E15,'SN01'!$G$3:$G$2001,"*") -> 0 | L15: =countifs('SN01'!$F$3:$F$2001,L$5,'SN01'!$D$3:$D$2001,$E15,'SN01'!$G$3:$G$2001,"*") -> 0 | M15: =countifs('SN01'!$F$3:$F$2001,M$5,'SN01'!$D$3:$D$2001,$E15,'SN01'!$G$3:$G$2001,"*") -> 0 | N15: =countifs('SN01'!$F$3:$F$2001,N$5,'SN01'!$D$3:$D$2001,$E15,'SN01'!$G$3:$G$2001,"*") -> 0 | ... AF15: =countifs('SN01'!$F$3:$F$2001,AF$5,'SN01'!$D$3:$D$2001,$E15,'SN01'!$G$3:$G$2001,"*") -> 0
B16: 2 | C16: Bùi Văn Tú | D16: =sum(H16:AK16) -> 0 | E16: G002@gdsonline.tech | F16: SN01 | G16: =countifs('SN01'!$F$3:$F$2001,G$5,'SN01'!$D$3:$D$2001,$E16,'SN01'!$G$3:$G$2001,"*") -> 0 | H16: =countifs('SN01'!$F$3:$F$2001,H$5,'SN01'!$D$3:$D$2001,$E16,'SN01'!$G$3:$G$2001,"*") -> 0 | I16: =countifs('SN01'!$F$3:$F$2001,I$5,'SN01'!$D$3:$D$2001,$E16,'SN01'!$G$3:$G$2001,"*") -> 0 | J16: =countifs('SN01'!$F$3:$F$2001,J$5,'SN01'!$D$3:$D$2001,$E16,'SN01'!$G$3:$G$2001,"*") -> 0 | K16: =countifs('SN01'!$F$3:$F$2001,K$5,'SN01'!$D$3:$D$2001,$E16,'SN01'!$G$3:$G$2001,"*") -> 0 | L16: =countifs('SN01'!$F$3:$F$2001,L$5,'SN01'!$D$3:$D$2001,$E16,'SN01'!$G$3:$G$2001,"*") -> 0 | M16: =countifs('SN01'!$F$3:$F$2001,M$5,'SN01'!$D$3:$D$2001,$E16,'SN01'!$G$3:$G$2001,"*") -> 0 | N16: =countifs('SN01'!$F$3:$F$2001,N$5,'SN01'!$D$3:$D$2001,$E16,'SN01'!$G$3:$G$2001,"*") -> 0 | ... AF16: =countifs('SN01'!$F$3:$F$2001,AF$5,'SN01'!$D$3:$D$2001,$E16,'SN01'!$G$3:$G$2001,"*") -> 0
B17: 3 | C17: Nguyễn Quang Quý | D17: =sum(H17:AK17) -> 0 | E17: G003@gdsonline.tech | F17: SN01 | G17: =countifs('SN01'!$F$3:$F$2001,G$5,'SN01'!$D$3:$D$2001,$E17,'SN01'!$G$3:$G$2001,"*") -> 0 | H17: =countifs('SN01'!$F$3:$F$2001,H$5,'SN01'!$D$3:$D$2001,$E17,'SN01'!$G$3:$G$2001,"*") -> 0 | I17: =countifs('SN01'!$F$3:$F$2001,I$5,'SN01'!$D$3:$D$2001,$E17,'SN01'!$G$3:$G$2001,"*") -> 0 | J17: =countifs('SN01'!$F$3:$F$2001,J$5,'SN01'!$D$3:$D$2001,$E17,'SN01'!$G$3:$G$2001,"*") -> 0 | K17: =countifs('SN01'!$F$3:$F$2001,K$5,'SN01'!$D$3:$D$2001,$E17,'SN01'!$G$3:$G$2001,"*") -> 0 | L17: =countifs('SN01'!$F$3:$F$2001,L$5,'SN01'!$D$3:$D$2001,$E17,'SN01'!$G$3:$G$2001,"*") -> 0 | M17: =countifs('SN01'!$F$3:$F$2001,M$5,'SN01'!$D$3:$D$2001,$E17,'SN01'!$G$3:$G$2001,"*") -> 0 | N17: =countifs('SN01'!$F$3:$F$2001,N$5,'SN01'!$D$3:$D$2001,$E17,'SN01'!$G$3:$G$2001,"*") -> 0 | ... AF17: =countifs('SN01'!$F$3:$F$2001,AF$5,'SN01'!$D$3:$D$2001,$E17,'SN01'!$G$3:$G$2001,"*") -> 0
B18: 4 | C18: Cấn Tất Dương | D18: =sum(H18:AK18) -> 0 | E18: G004@gdsonline.tech | F18: SN01 | G18: =countifs('SN01'!$F$3:$F$2001,G$5,'SN01'!$D$3:$D$2001,$E18,'SN01'!$G$3:$G$2001,"*") -> 0 | H18: =countifs('SN01'!$F$3:$F$2001,H$5,'SN01'!$D$3:$D$2001,$E18,'SN01'!$G$3:$G$2001,"*") -> 0 | I18: =countifs('SN01'!$F$3:$F$2001,I$5,'SN01'!$D$3:$D$2001,$E18,'SN01'!$G$3:$G$2001,"*") -> 0 | J18: =countifs('SN01'!$F$3:$F$2001,J$5,'SN01'!$D$3:$D$2001,$E18,'SN01'!$G$3:$G$2001,"*") -> 0 | K18: =countifs('SN01'!$F$3:$F$2001,K$5,'SN01'!$D$3:$D$2001,$E18,'SN01'!$G$3:$G$2001,"*") -> 0 | L18: =countifs('SN01'!$F$3:$F$2001,L$5,'SN01'!$D$3:$D$2001,$E18,'SN01'!$G$3:$G$2001,"*") -> 0 | M18: =countifs('SN01'!$F$3:$F$2001,M$5,'SN01'!$D$3:$D$2001,$E18,'SN01'!$G$3:$G$2001,"*") -> 0 | N18: =countifs('SN01'!$F$3:$F$2001,N$5,'SN01'!$D$3:$D$2001,$E18,'SN01'!$G$3:$G$2001,"*") -> 0 | ... AF18: =countifs('SN01'!$F$3:$F$2001,AF$5,'SN01'!$D$3:$D$2001,$E18,'SN01'!$G$3:$G$2001,"*") -> 0
B19: 5 | C19: Nông Văn Sâm | D19: =sum(H19:AK19) -> 0 | E19: G005@gdsonline.tech | F19: SN01 | G19: =countifs('SN01'!$F$3:$F$2001,G$5,'SN01'!$D$3:$D$2001,$E19,'SN01'!$G$3:$G$2001,"*") -> 0 | H19: =countifs('SN01'!$F$3:$F$2001,H$5,'SN01'!$D$3:$D$2001,$E19,'SN01'!$G$3:$G$2001,"*") -> 0 | I19: =countifs('SN01'!$F$3:$F$2001,I$5,'SN01'!$D$3:$D$2001,$E19,'SN01'!$G$3:$G$2001,"*") -> 0 | J19: =countifs('SN01'!$F$3:$F$2001,J$5,'SN01'!$D$3:$D$2001,$E19,'SN01'!$G$3:$G$2001,"*") -> 0 | K19: =countifs('SN01'!$F$3:$F$2001,K$5,'SN01'!$D$3:$D$2001,$E19,'SN01'!$G$3:$G$2001,"*") -> 0 | L19: =countifs('SN01'!$F$3:$F$2001,L$5,'SN01'!$D$3:$D$2001,$E19,'SN01'!$G$3:$G$2001,"*") -> 0 | M19: =countifs('SN01'!$F$3:$F$2001,M$5,'SN01'!$D$3:$D$2001,$E19,'SN01'!$G$3:$G$2001,"*") -> 0 | N19: =countifs('SN01'!$F$3:$F$2001,N$5,'SN01'!$D$3:$D$2001,$E19,'SN01'!$G$3:$G$2001,"*") -> 0 | ... AF19: =countifs('SN01'!$F$3:$F$2001,AF$5,'SN01'!$D$3:$D$2001,$E19,'SN01'!$G$3:$G$2001,"*") -> 0
B20: 6 | C20: Nguyễn Minh Quang | D20: =sum(H20:AK20) -> 0 | E20: G006@gdsonline.tech | F20: SN01 | G20: =countifs('SN01'!$F$3:$F$2001,G$5,'SN01'!$D$3:$D$2001,$E20,'SN01'!$G$3:$G$2001,"*") -> 0 | H20: =countifs('SN01'!$F$3:$F$2001,H$5,'SN01'!$D$3:$D$2001,$E20,'SN01'!$G$3:$G$2001,"*") -> 0 | I20: =countifs('SN01'!$F$3:$F$2001,I$5,'SN01'!$D$3:$D$2001,$E20,'SN01'!$G$3:$G$2001,"*") -> 0 | J20: =countifs('SN01'!$F$3:$F$2001,J$5,'SN01'!$D$3:$D$2001,$E20,'SN01'!$G$3:$G$2001,"*") -> 0 | K20: =countifs('SN01'!$F$3:$F$2001,K$5,'SN01'!$D$3:$D$2001,$E20,'SN01'!$G$3:$G$2001,"*") -> 0 | L20: =countifs('SN01'!$F$3:$F$2001,L$5,'SN01'!$D$3:$D$2001,$E20,'SN01'!$G$3:$G$2001,"*") -> 0 | M20: =countifs('SN01'!$F$3:$F$2001,M$5,'SN01'!$D$3:$D$2001,$E20,'SN01'!$G$3:$G$2001,"*") -> 0 | N20: =countifs('SN01'!$F$3:$F$2001,N$5,'SN01'!$D$3:$D$2001,$E20,'SN01'!$G$3:$G$2001,"*") -> 0 | ... AF20: =countifs('SN01'!$F$3:$F$2001,AF$5,'SN01'!$D$3:$D$2001,$E20,'SN01'!$G$3:$G$2001,"*") -> 0
B21: 21 | C21: Nguyễn Anh Đức | D21: =sum(H21:AK21) -> 0 | E21: G020@gdsonline.tech | F21: SN01 | G21: =countifs('SN01'!$F$3:$F$2001,G$5,'SN01'!$D$3:$D$2001,$E21,'SN01'!$G$3:$G$2001,"*") -> 0 | H21: =countifs('SN01'!$F$3:$F$2001,H$5,'SN01'!$D$3:$D$2001,$E21,'SN01'!$G$3:$G$2001,"*") -> 0 | I21: =countifs('SN01'!$F$3:$F$2001,I$5,'SN01'!$D$3:$D$2001,$E21,'SN01'!$G$3:$G$2001,"*") -> 0 | J21: =countifs('SN01'!$F$3:$F$2001,J$5,'SN01'!$D$3:$D$2001,$E21,'SN01'!$G$3:$G$2001,"*") -> 0 | K21: =countifs('SN01'!$F$3:$F$2001,K$5,'SN01'!$D$3:$D$2001,$E21,'SN01'!$G$3:$G$2001,"*") -> 0 | L21: =countifs('SN01'!$F$3:$F$2001,L$5,'SN01'!$D$3:$D$2001,$E21,'SN01'!$G$3:$G$2001,"*") -> 0 | M21: =countifs('SN01'!$F$3:$F$2001,M$5,'SN01'!$D$3:$D$2001,$E21,'SN01'!$G$3:$G$2001,"*") -> 0 | N21: =countifs('SN01'!$F$3:$F$2001,N$5,'SN01'!$D$3:$D$2001,$E21,'SN01'!$G$3:$G$2001,"*") -> 0 | ... AF21: =countifs('SN01'!$F$3:$F$2001,AF$5,'SN01'!$D$3:$D$2001,$E21,'SN01'!$G$3:$G$2001,"*") -> 0
B22: 7 | C22: Dương Kim Nam | D22: =sum(H22:AK22) -> 64 | E22: G007@gdsonline.tech | F22: SN02 | G22: =countifs('SN02'!$F$3:$F$781,G$5,'SN02'!$D$3:$D$781,$E22,'SN02'!$G$3:$G$781,"*") -> 0 | H22: =countifs('SN02'!$F$3:$F$781,H$5,'SN02'!$D$3:$D$781,$E22,'SN02'!$G$3:$G$781,"*") -> 0 | I22: =countifs('SN02'!$F$3:$F$781,I$5,'SN02'!$D$3:$D$781,$E22,'SN02'!$G$3:$G$781,"*") -> 0 | J22: =countifs('SN02'!$F$3:$F$781,J$5,'SN02'!$D$3:$D$781,$E22,'SN02'!$G$3:$G$781,"*") -> 10 | K22: =countifs('SN02'!$F$3:$F$781,K$5,'SN02'!$D$3:$D$781,$E22,'SN02'!$G$3:$G$781,"*") -> 52 | L22: =countifs('SN02'!$F$3:$F$781,L$5,'SN02'!$D$3:$D$781,$E22,'SN02'!$G$3:$G$781,"*") -> 0 | M22: =countifs('SN02'!$F$3:$F$781,M$5,'SN02'!$D$3:$D$781,$E22,'SN02'!$G$3:$G$781,"*") -> 1 | N22: =countifs('SN02'!$F$3:$F$781,N$5,'SN02'!$D$3:$D$781,$E22,'SN02'!$G$3:$G$781,"*") -> 0 | ... AF22: =countifs('SN02'!$F$3:$F$781,AF$5,'SN02'!$D$3:$D$781,$E22,'SN02'!$G$3:$G$781,"*") -> 0
B23: 8 | C23: Nguyễn Ngọc Tân | D23: =sum(H23:AK23) -> 146 | E23: G008@gdsonline.tech | F23: SN02 | G23: =countifs('SN02'!$F$3:$F$781,G$5,'SN02'!$D$3:$D$781,$E23,'SN02'!$G$3:$G$781,"*") -> 0 | H23: =countifs('SN02'!$F$3:$F$781,H$5,'SN02'!$D$3:$D$781,$E23,'SN02'!$G$3:$G$781,"*") -> 0 | I23: =countifs('SN02'!$F$3:$F$781,I$5,'SN02'!$D$3:$D$781,$E23,'SN02'!$G$3:$G$781,"*") -> 0 | J23: =countifs('SN02'!$F$3:$F$781,J$5,'SN02'!$D$3:$D$781,$E23,'SN02'!$G$3:$G$781,"*") -> 40 | K23: =countifs('SN02'!$F$3:$F$781,K$5,'SN02'!$D$3:$D$781,$E23,'SN02'!$G$3:$G$781,"*") -> 25 | L23: =countifs('SN02'!$F$3:$F$781,L$5,'SN02'!$D$3:$D$781,$E23,'SN02'!$G$3:$G$781,"*") -> 10 | M23: =countifs('SN02'!$F$3:$F$781,M$5,'SN02'!$D$3:$D$781,$E23,'SN02'!$G$3:$G$781,"*") -> 11 | N23: =countifs('SN02'!$F$3:$F$781,N$5,'SN02'!$D$3:$D$781,$E23,'SN02'!$G$3:$G$781,"*") -> 5 | ... AF23: =countifs('SN02'!$F$3:$F$781,AF$5,'SN02'!$D$3:$D$781,$E23,'SN02'!$G$3:$G$781,"*") -> 0
B24: 9 | C24: Đỗ Mạnh Tùng | D24: =sum(H24:AK24) -> 156 | E24: G009@gdsonline.tech | F24: SN02 | G24: =countifs('SN02'!$F$3:$F$781,G$5,'SN02'!$D$3:$D$781,$E24,'SN02'!$G$3:$G$781,"*") -> 0 | H24: =countifs('SN02'!$F$3:$F$781,H$5,'SN02'!$D$3:$D$781,$E24,'SN02'!$G$3:$G$781,"*") -> 0 | I24: =countifs('SN02'!$F$3:$F$781,I$5,'SN02'!$D$3:$D$781,$E24,'SN02'!$G$3:$G$781,"*") -> 0 | J24: =countifs('SN02'!$F$3:$F$781,J$5,'SN02'!$D$3:$D$781,$E24,'SN02'!$G$3:$G$781,"*") -> 60 | K24: =countifs('SN02'!$F$3:$F$781,K$5,'SN02'!$D$3:$D$781,$E24,'SN02'!$G$3:$G$781,"*") -> 0 | L24: =countifs('SN02'!$F$3:$F$781,L$5,'SN02'!$D$3:$D$781,$E24,'SN02'!$G$3:$G$781,"*") -> 15 | M24: =countifs('SN02'!$F$3:$F$781,M$5,'SN02'!$D$3:$D$781,$E24,'SN02'!$G$3:$G$781,"*") -> 15 | N24: =countifs('SN02'!$F$3:$F$781,N$5,'SN02'!$D$3:$D$781,$E24,'SN02'!$G$3:$G$781,"*") -> 0 | ... AF24: =countifs('SN02'!$F$3:$F$781,AF$5,'SN02'!$D$3:$D$781,$E24,'SN02'!$G$3:$G$781,"*") -> 0
B25: 10 | C25: Nguyễn Xuân Công | D25: =sum(H25:AK25) -> 142 | E25: G010@gdsonline.tech | F25: SN02 | G25: =countifs('SN02'!$F$3:$F$781,G$5,'SN02'!$D$3:$D$781,$E25,'SN02'!$G$3:$G$781,"*") -> 0 | H25: =countifs('SN02'!$F$3:$F$781,H$5,'SN02'!$D$3:$D$781,$E25,'SN02'!$G$3:$G$781,"*") -> 0 | I25: =countifs('SN02'!$F$3:$F$781,I$5,'SN02'!$D$3:$D$781,$E25,'SN02'!$G$3:$G$781,"*") -> 0 | J25: =countifs('SN02'!$F$3:$F$781,J$5,'SN02'!$D$3:$D$781,$E25,'SN02'!$G$3:$G$781,"*") -> 0 | K25: =countifs('SN02'!$F$3:$F$781,K$5,'SN02'!$D$3:$D$781,$E25,'SN02'!$G$3:$G$781,"*") -> 0 | L25: =countifs('SN02'!$F$3:$F$781,L$5,'SN02'!$D$3:$D$781,$E25,'SN02'!$G$3:$G$781,"*") -> 10 | M25: =countifs('SN02'!$F$3:$F$781,M$5,'SN02'!$D$3:$D$781,$E25,'SN02'!$G$3:$G$781,"*") -> 10 | N25: =countifs('SN02'!$F$3:$F$781,N$5,'SN02'!$D$3:$D$781,$E25,'SN02'!$G$3:$G$781,"*") -> 10 | ... AF25: =countifs('SN02'!$F$3:$F$781,AF$5,'SN02'!$D$3:$D$781,$E25,'SN02'!$G$3:$G$781,"*") -> 0
B26: 11 | C26: Phan Nguyễn Tuấn Minh | D26: =sum(H26:AK26) -> 129 | E26: G011@gdsonline.tech | F26: SN02 | G26: =countifs('SN02'!$F$3:$F$781,G$5,'SN02'!$D$3:$D$781,$E26,'SN02'!$G$3:$G$781,"*") -> 0 | H26: =countifs('SN02'!$F$3:$F$781,H$5,'SN02'!$D$3:$D$781,$E26,'SN02'!$G$3:$G$781,"*") -> 0 | I26: =countifs('SN02'!$F$3:$F$781,I$5,'SN02'!$D$3:$D$781,$E26,'SN02'!$G$3:$G$781,"*") -> 0 | J26: =countifs('SN02'!$F$3:$F$781,J$5,'SN02'!$D$3:$D$781,$E26,'SN02'!$G$3:$G$781,"*") -> 14 | K26: =countifs('SN02'!$F$3:$F$781,K$5,'SN02'!$D$3:$D$781,$E26,'SN02'!$G$3:$G$781,"*") -> 29 | L26: =countifs('SN02'!$F$3:$F$781,L$5,'SN02'!$D$3:$D$781,$E26,'SN02'!$G$3:$G$781,"*") -> 12 | M26: =countifs('SN02'!$F$3:$F$781,M$5,'SN02'!$D$3:$D$781,$E26,'SN02'!$G$3:$G$781,"*") -> 14 | N26: =countifs('SN02'!$F$3:$F$781,N$5,'SN02'!$D$3:$D$781,$E26,'SN02'!$G$3:$G$781,"*") -> 5 | ... AF26: =countifs('SN02'!$F$3:$F$781,AF$5,'SN02'!$D$3:$D$781,$E26,'SN02'!$G$3:$G$781,"*") -> 0
B27: 12 | C27: Nguyễn Ngọc Hân | D27: =sum(H27:AK27) -> 53 | E27: G012@gdsonline.tech | F27: SN02 | G27: =countifs('SN02'!$F$3:$F$781,G$5,'SN02'!$D$3:$D$781,$E27,'SN02'!$G$3:$G$781,"*") -> 0 | H27: =countifs('SN02'!$F$3:$F$781,H$5,'SN02'!$D$3:$D$781,$E27,'SN02'!$G$3:$G$781,"*") -> 0 | I27: =countifs('SN02'!$F$3:$F$781,I$5,'SN02'!$D$3:$D$781,$E27,'SN02'!$G$3:$G$781,"*") -> 0 | J27: =countifs('SN02'!$F$3:$F$781,J$5,'SN02'!$D$3:$D$781,$E27,'SN02'!$G$3:$G$781,"*") -> 0 | K27: =countifs('SN02'!$F$3:$F$781,K$5,'SN02'!$D$3:$D$781,$E27,'SN02'!$G$3:$G$781,"*") -> 0 | L27: =countifs('SN02'!$F$3:$F$781,L$5,'SN02'!$D$3:$D$781,$E27,'SN02'!$G$3:$G$781,"*") -> 8 | M27: =countifs('SN02'!$F$3:$F$781,M$5,'SN02'!$D$3:$D$781,$E27,'SN02'!$G$3:$G$781,"*") -> 4 | N27: =countifs('SN02'!$F$3:$F$781,N$5,'SN02'!$D$3:$D$781,$E27,'SN02'!$G$3:$G$781,"*") -> 2 | ... AF27: =countifs('SN02'!$F$3:$F$781,AF$5,'SN02'!$D$3:$D$781,$E27,'SN02'!$G$3:$G$781,"*") -> 0
B28: 13 | C28: Nguyễn Đức Ban | D28: =sum(H28:AK28) -> 64 | E28: G013@gdsonline.tech | F28: SN02 | G28: =countifs('SN02'!$F$3:$F$781,G$5,'SN02'!$D$3:$D$781,$E28,'SN02'!$G$3:$G$781,"*") -> 0 | H28: =countifs('SN02'!$F$3:$F$781,H$5,'SN02'!$D$3:$D$781,$E28,'SN02'!$G$3:$G$781,"*") -> 0 | I28: =countifs('SN02'!$F$3:$F$781,I$5,'SN02'!$D$3:$D$781,$E28,'SN02'!$G$3:$G$781,"*") -> 0 | J28: =countifs('SN02'!$F$3:$F$781,J$5,'SN02'!$D$3:$D$781,$E28,'SN02'!$G$3:$G$781,"*") -> 0 | K28: =countifs('SN02'!$F$3:$F$781,K$5,'SN02'!$D$3:$D$781,$E28,'SN02'!$G$3:$G$781,"*") -> 0 | L28: =countifs('SN02'!$F$3:$F$781,L$5,'SN02'!$D$3:$D$781,$E28,'SN02'!$G$3:$G$781,"*") -> 1 | M28: =countifs('SN02'!$F$3:$F$781,M$5,'SN02'!$D$3:$D$781,$E28,'SN02'!$G$3:$G$781,"*") -> 0 | N28: =countifs('SN02'!$F$3:$F$781,N$5,'SN02'!$D$3:$D$781,$E28,'SN02'!$G$3:$G$781,"*") -> 0 | ... AF28: =countifs('SN02'!$F$3:$F$781,AF$5,'SN02'!$D$3:$D$781,$E28,'SN02'!$G$3:$G$781,"*") -> 7
B29: 15 | C29: Đinh Thị Yến | D29: =sum(H29:AK29) -> 0 | E29: G015@gdsonline.tech | F29: SN03 | G29: =countifs('SN03'!$F$3:$F$2000,G$5,'SN03'!$D$3:$D$2000,$E29,'SN03'!$G$3:$G$2000,"*") -> 0 | H29: =countifs('SN03'!$F$3:$F$2000,H$5,'SN03'!$D$3:$D$2000,$E29,'SN03'!$G$3:$G$2000,"*") -> 0 | I29: =countifs('SN03'!$F$3:$F$2000,I$5,'SN03'!$D$3:$D$2000,$E29,'SN03'!$G$3:$G$2000,"*") -> 0 | J29: =countifs('SN03'!$F$3:$F$2000,J$5,'SN03'!$D$3:$D$2000,$E29,'SN03'!$G$3:$G$2000,"*") -> 0 | K29: =countifs('SN03'!$F$3:$F$2000,K$5,'SN03'!$D$3:$D$2000,$E29,'SN03'!$G$3:$G$2000,"*") -> 0 | L29: =countifs('SN03'!$F$3:$F$2000,L$5,'SN03'!$D$3:$D$2000,$E29,'SN03'!$G$3:$G$2000,"*") -> 0 | M29: =countifs('SN03'!$F$3:$F$2000,M$5,'SN03'!$D$3:$D$2000,$E29,'SN03'!$G$3:$G$2000,"*") -> 0 | N29: =countifs('SN03'!$F$3:$F$2000,N$5,'SN03'!$D$3:$D$2000,$E29,'SN03'!$G$3:$G$2000,"*") -> 0 | ... AF29: =countifs('SN03'!$F$3:$F$2000,AF$5,'SN03'!$D$3:$D$2000,$E29,'SN03'!$G$3:$G$2000,"*") -> 0
B30: 16 | D30: =sum(H30:AK30) -> 0 | E30: QuynhTTN@ltsgroup.tech | F30: SN04 | G30: =countifs('SN04'!$F$2:$F$7926,G$5,'SN04'!$D$2:$D$7926,$E30,'SN04'!$G$2:$G$7926,"*") -> 0 | H30: =countifs('SN04'!$F$2:$F$7926,H$5,'SN04'!$D$2:$D$7926,$E30,'SN04'!$G$2:$G$7926,"*") -> 0 | I30: =countifs('SN04'!$F$2:$F$7926,I$5,'SN04'!$D$2:$D$7926,$E30,'SN04'!$G$2:$G$7926,"*") -> 0 | J30: =countifs('SN04'!$F$2:$F$7926,J$5,'SN04'!$D$2:$D$7926,$E30,'SN04'!$G$2:$G$7926,"*") -> 0 | K30: =countifs('SN04'!$F$2:$F$7926,K$5,'SN04'!$D$2:$D$7926,$E30,'SN04'!$G$2:$G$7926,"*") -> 0 | L30: =countifs('SN04'!$F$2:$F$7926,L$5,'SN04'!$D$2:$D$7926,$E30,'SN04'!$G$2:$G$7926,"*") -> 0 | M30: =countifs('SN04'!$F$2:$F$7926,M$5,'SN04'!$D$2:$D$7926,$E30,'SN04'!$G$2:$G$7926,"*") -> 0 | N30: =countifs('SN04'!$F$2:$F$7926,N$5,'SN04'!$D$2:$D$7926,$E30,'SN04'!$G$2:$G$7926,"*") -> 0 | ... AF30: =countifs('SN04'!$F$2:$F$7926,AF$5,'SN04'!$D$2:$D$7926,$E30,'SN04'!$G$2:$G$7926,"*") -> 0
B31: 17 | C31: Bùi Thế Anh | D31: =sum(H31:AK31) -> 0 | E31: G016@gdsonline.tech | F31: SN04 | G31: =countifs('SN04'!$F$2:$F$7926,G$5,'SN04'!$D$2:$D$7926,$E31,'SN04'!$G$2:$G$7926,"*") -> 0 | H31: =countifs('SN04'!$F$2:$F$7926,H$5,'SN04'!$D$2:$D$7926,$E31,'SN04'!$G$2:$G$7926,"*") -> 0 | I31: =countifs('SN04'!$F$2:$F$7926,I$5,'SN04'!$D$2:$D$7926,$E31,'SN04'!$G$2:$G$7926,"*") -> 0 | J31: =countifs('SN04'!$F$2:$F$7926,J$5,'SN04'!$D$2:$D$7926,$E31,'SN04'!$G$2:$G$7926,"*") -> 0 | K31: =countifs('SN04'!$F$2:$F$7926,K$5,'SN04'!$D$2:$D$7926,$E31,'SN04'!$G$2:$G$7926,"*") -> 0 | L31: =countifs('SN04'!$F$2:$F$7926,L$5,'SN04'!$D$2:$D$7926,$E31,'SN04'!$G$2:$G$7926,"*") -> 0 | M31: =countifs('SN04'!$F$2:$F$7926,M$5,'SN04'!$D$2:$D$7926,$E31,'SN04'!$G$2:$G$7926,"*") -> 0 | N31: =countifs('SN04'!$F$2:$F$7926,N$5,'SN04'!$D$2:$D$7926,$E31,'SN04'!$G$2:$G$7926,"*") -> 0 | ... AF31: =countifs('SN04'!$F$2:$F$7926,AF$5,'SN04'!$D$2:$D$7926,$E31,'SN04'!$G$2:$G$7926,"*") -> 0
B32: 18 | C32: Nguyễn Thị Phương Anh | D32: =sum(H32:AK32) -> 0 | E32: G017@gdsonline.tech | F32: SN04 | G32: =countifs('SN04'!$F$2:$F$7926,G$5,'SN04'!$D$2:$D$7926,$E32,'SN04'!$G$2:$G$7926,"*") -> 0 | H32: =countifs('SN04'!$F$2:$F$7926,H$5,'SN04'!$D$2:$D$7926,$E32,'SN04'!$G$2:$G$7926,"*") -> 0 | I32: =countifs('SN04'!$F$2:$F$7926,I$5,'SN04'!$D$2:$D$7926,$E32,'SN04'!$G$2:$G$7926,"*") -> 0 | J32: =countifs('SN04'!$F$2:$F$7926,J$5,'SN04'!$D$2:$D$7926,$E32,'SN04'!$G$2:$G$7926,"*") -> 0 | K32: =countifs('SN04'!$F$2:$F$7926,K$5,'SN04'!$D$2:$D$7926,$E32,'SN04'!$G$2:$G$7926,"*") -> 0 | L32: =countifs('SN04'!$F$2:$F$7926,L$5,'SN04'!$D$2:$D$7926,$E32,'SN04'!$G$2:$G$7926,"*") -> 0 | M32: =countifs('SN04'!$F$2:$F$7926,M$5,'SN04'!$D$2:$D$7926,$E32,'SN04'!$G$2:$G$7926,"*") -> 0 | N32: =countifs('SN04'!$F$2:$F$7926,N$5,'SN04'!$D$2:$D$7926,$E32,'SN04'!$G$2:$G$7926,"*") -> 0 | ... AF32: =countifs('SN04'!$F$2:$F$7926,AF$5,'SN04'!$D$2:$D$7926,$E32,'SN04'!$G$2:$G$7926,"*") -> 0
B33: 19 | C33: Nguyễn Văn Hùng | D33: =sum(H33:AK33) -> 0 | E33: G018@gdsonline.tech | F33: SN04 | G33: =countifs('SN04'!$F$2:$F$7926,G$5,'SN04'!$D$2:$D$7926,$E33,'SN04'!$G$2:$G$7926,"*") -> 0 | H33: =countifs('SN04'!$F$2:$F$7926,H$5,'SN04'!$D$2:$D$7926,$E33,'SN04'!$G$2:$G$7926,"*") -> 0 | I33: =countifs('SN04'!$F$2:$F$7926,I$5,'SN04'!$D$2:$D$7926,$E33,'SN04'!$G$2:$G$7926,"*") -> 0 | J33: =countifs('SN04'!$F$2:$F$7926,J$5,'SN04'!$D$2:$D$7926,$E33,'SN04'!$G$2:$G$7926,"*") -> 0 | K33: =countifs('SN04'!$F$2:$F$7926,K$5,'SN04'!$D$2:$D$7926,$E33,'SN04'!$G$2:$G$7926,"*") -> 0 | L33: =countifs('SN04'!$F$2:$F$7926,L$5,'SN04'!$D$2:$D$7926,$E33,'SN04'!$G$2:$G$7926,"*") -> 0 | M33: =countifs('SN04'!$F$2:$F$7926,M$5,'SN04'!$D$2:$D$7926,$E33,'SN04'!$G$2:$G$7926,"*") -> 0 | N33: =countifs('SN04'!$F$2:$F$7926,N$5,'SN04'!$D$2:$D$7926,$E33,'SN04'!$G$2:$G$7926,"*") -> 0 | ... AF33: =countifs('SN04'!$F$2:$F$7926,AF$5,'SN04'!$D$2:$D$7926,$E33,'SN04'!$G$2:$G$7926,"*") -> 0
B34: 20 | C34: Dương Văn Minh Duy | D34: =sum(H34:AK34) -> 0 | E34: G019@gdsonline.tech | F34: SN04 | G34: =countifs('SN04'!$F$2:$F$7926,G$5,'SN04'!$D$2:$D$7926,$E34,'SN04'!$G$2:$G$7926,"*") -> 0 | H34: =countifs('SN04'!$F$2:$F$7926,H$5,'SN04'!$D$2:$D$7926,$E34,'SN04'!$G$2:$G$7926,"*") -> 0 | I34: =countifs('SN04'!$F$2:$F$7926,I$5,'SN04'!$D$2:$D$7926,$E34,'SN04'!$G$2:$G$7926,"*") -> 0 | J34: =countifs('SN04'!$F$2:$F$7926,J$5,'SN04'!$D$2:$D$7926,$E34,'SN04'!$G$2:$G$7926,"*") -> 0 | K34: =countifs('SN04'!$F$2:$F$7926,K$5,'SN04'!$D$2:$D$7926,$E34,'SN04'!$G$2:$G$7926,"*") -> 0 | L34: =countifs('SN04'!$F$2:$F$7926,L$5,'SN04'!$D$2:$D$7926,$E34,'SN04'!$G$2:$G$7926,"*") -> 0 | M34: =countifs('SN04'!$F$2:$F$7926,M$5,'SN04'!$D$2:$D$7926,$E34,'SN04'!$G$2:$G$7926,"*") -> 0 | N34: =countifs('SN04'!$F$2:$F$7926,N$5,'SN04'!$D$2:$D$7926,$E34,'SN04'!$G$2:$G$7926,"*") -> 0 | ... AF34: =countifs('SN04'!$F$2:$F$7926,AF$5,'SN04'!$D$2:$D$7926,$E34,'SN04'!$G$2:$G$7926,"*") -> 0
B35: 22 | C35: Nguyễn Hải Yến | D35: =sum(H35:AK35) -> 0 | E35: G021@gdsonline.tech | F35: SN04 | G35: =countifs('SN04'!$F$2:$F$7926,G$5,'SN04'!$D$2:$D$7926,$E35,'SN04'!$G$2:$G$7926,"*") -> 0 | H35: =countifs('SN04'!$F$2:$F$7926,H$5,'SN04'!$D$2:$D$7926,$E35,'SN04'!$G$2:$G$7926,"*") -> 0 | I35: =countifs('SN04'!$F$2:$F$7926,I$5,'SN04'!$D$2:$D$7926,$E35,'SN04'!$G$2:$G$7926,"*") -> 0 | J35: =countifs('SN04'!$F$2:$F$7926,J$5,'SN04'!$D$2:$D$7926,$E35,'SN04'!$G$2:$G$7926,"*") -> 0 | K35: =countifs('SN04'!$F$2:$F$7926,K$5,'SN04'!$D$2:$D$7926,$E35,'SN04'!$G$2:$G$7926,"*") -> 0 | L35: =countifs('SN04'!$F$2:$F$7926,L$5,'SN04'!$D$2:$D$7926,$E35,'SN04'!$G$2:$G$7926,"*") -> 0 | M35: =countifs('SN04'!$F$2:$F$7926,M$5,'SN04'!$D$2:$D$7926,$E35,'SN04'!$G$2:$G$7926,"*") -> 0 | N35: =countifs('SN04'!$F$2:$F$7926,N$5,'SN04'!$D$2:$D$7926,$E35,'SN04'!$G$2:$G$7926,"*") -> 0 | ... AF35: =countifs('SN04'!$F$2:$F$7926,AF$5,'SN04'!$D$2:$D$7926,$E35,'SN04'!$G$2:$G$7926,"*") -> 0
B36: 23 | C36: Hoàng Mai Linh | D36: =sum(H36:AK36) -> 0 | E36: G022@gdsonline.tech | F36: SN04 | G36: =countifs('SN04'!$F$2:$F$7926,G$5,'SN04'!$D$2:$D$7926,$E36,'SN04'!$G$2:$G$7926,"*") -> 0 | H36: =countifs('SN04'!$F$2:$F$7926,H$5,'SN04'!$D$2:$D$7926,$E36,'SN04'!$G$2:$G$7926,"*") -> 0 | I36: =countifs('SN04'!$F$2:$F$7926,I$5,'SN04'!$D$2:$D$7926,$E36,'SN04'!$G$2:$G$7926,"*") -> 0 | J36: =countifs('SN04'!$F$2:$F$7926,J$5,'SN04'!$D$2:$D$7926,$E36,'SN04'!$G$2:$G$7926,"*") -> 0 | K36: =countifs('SN04'!$F$2:$F$7926,K$5,'SN04'!$D$2:$D$7926,$E36,'SN04'!$G$2:$G$7926,"*") -> 0 | L36: =countifs('SN04'!$F$2:$F$7926,L$5,'SN04'!$D$2:$D$7926,$E36,'SN04'!$G$2:$G$7926,"*") -> 0 | M36: =countifs('SN04'!$F$2:$F$7926,M$5,'SN04'!$D$2:$D$7926,$E36,'SN04'!$G$2:$G$7926,"*") -> 0 | N36: =countifs('SN04'!$F$2:$F$7926,N$5,'SN04'!$D$2:$D$7926,$E36,'SN04'!$G$2:$G$7926,"*") -> 0 | ... AF36: =countifs('SN04'!$F$2:$F$7926,AF$5,'SN04'!$D$2:$D$7926,$E36,'SN04'!$G$2:$G$7926,"*") -> 0
B37: 24 | C37: Nguyễn Hoàng Anh | D37: =sum(H37:AK37) -> 0 | E37: G023@gdsonline.tech | F37: SN04 | G37: =countifs('SN04'!$F$2:$F$7926,G$5,'SN04'!$D$2:$D$7926,$E37,'SN04'!$G$2:$G$7926,"*") -> 0 | H37: =countifs('SN04'!$F$2:$F$7926,H$5,'SN04'!$D$2:$D$7926,$E37,'SN04'!$G$2:$G$7926,"*") -> 0 | I37: =countifs('SN04'!$F$2:$F$7926,I$5,'SN04'!$D$2:$D$7926,$E37,'SN04'!$G$2:$G$7926,"*") -> 0 | J37: =countifs('SN04'!$F$2:$F$7926,J$5,'SN04'!$D$2:$D$7926,$E37,'SN04'!$G$2:$G$7926,"*") -> 0 | K37: =countifs('SN04'!$F$2:$F$7926,K$5,'SN04'!$D$2:$D$7926,$E37,'SN04'!$G$2:$G$7926,"*") -> 0 | L37: =countifs('SN04'!$F$2:$F$7926,L$5,'SN04'!$D$2:$D$7926,$E37,'SN04'!$G$2:$G$7926,"*") -> 0 | M37: =countifs('SN04'!$F$2:$F$7926,M$5,'SN04'!$D$2:$D$7926,$E37,'SN04'!$G$2:$G$7926,"*") -> 0 | N37: =countifs('SN04'!$F$2:$F$7926,N$5,'SN04'!$D$2:$D$7926,$E37,'SN04'!$G$2:$G$7926,"*") -> 0 | ... AF37: =countifs('SN04'!$F$2:$F$7926,AF$5,'SN04'!$D$2:$D$7926,$E37,'SN04'!$G$2:$G$7926,"*") -> 0
B38: 25 | C38: Cao Thị Ngọc Mai | D38: =sum(H38:AK38) -> 0 | E38: G024@gdsonline.tech | F38: SN04 | G38: =countifs('SN04'!$F$2:$F$7926,G$5,'SN04'!$D$2:$D$7926,$E38,'SN04'!$G$2:$G$7926,"*") -> 0 | H38: =countifs('SN04'!$F$2:$F$7926,H$5,'SN04'!$D$2:$D$7926,$E38,'SN04'!$G$2:$G$7926,"*") -> 0 | I38: =countifs('SN04'!$F$2:$F$7926,I$5,'SN04'!$D$2:$D$7926,$E38,'SN04'!$G$2:$G$7926,"*") -> 0 | J38: =countifs('SN04'!$F$2:$F$7926,J$5,'SN04'!$D$2:$D$7926,$E38,'SN04'!$G$2:$G$7926,"*") -> 0 | K38: =countifs('SN04'!$F$2:$F$7926,K$5,'SN04'!$D$2:$D$7926,$E38,'SN04'!$G$2:$G$7926,"*") -> 0 | L38: =countifs('SN04'!$F$2:$F$7926,L$5,'SN04'!$D$2:$D$7926,$E38,'SN04'!$G$2:$G$7926,"*") -> 0 | M38: =countifs('SN04'!$F$2:$F$7926,M$5,'SN04'!$D$2:$D$7926,$E38,'SN04'!$G$2:$G$7926,"*") -> 0 | N38: =countifs('SN04'!$F$2:$F$7926,N$5,'SN04'!$D$2:$D$7926,$E38,'SN04'!$G$2:$G$7926,"*") -> 0 | ... AF38: =countifs('SN04'!$F$2:$F$7926,AF$5,'SN04'!$D$2:$D$7926,$E38,'SN04'!$G$2:$G$7926,"*") -> 0
B39: 26 | C39: Nguyễn Quang Vũ | D39: =sum(H39:AK39) -> 0 | E39: G025@gdsonline.tech | F39: SN04 | G39: =countifs('SN04'!$F$2:$F$7926,G$5,'SN04'!$D$2:$D$7926,$E39,'SN04'!$G$2:$G$7926,"*") -> 0 | H39: =countifs('SN04'!$F$2:$F$7926,H$5,'SN04'!$D$2:$D$7926,$E39,'SN04'!$G$2:$G$7926,"*") -> 0 | I39: =countifs('SN04'!$F$2:$F$7926,I$5,'SN04'!$D$2:$D$7926,$E39,'SN04'!$G$2:$G$7926,"*") -> 0 | J39: =countifs('SN04'!$F$2:$F$7926,J$5,'SN04'!$D$2:$D$7926,$E39,'SN04'!$G$2:$G$7926,"*") -> 0 | K39: =countifs('SN04'!$F$2:$F$7926,K$5,'SN04'!$D$2:$D$7926,$E39,'SN04'!$G$2:$G$7926,"*") -> 0 | L39: =countifs('SN04'!$F$2:$F$7926,L$5,'SN04'!$D$2:$D$7926,$E39,'SN04'!$G$2:$G$7926,"*") -> 0 | M39: =countifs('SN04'!$F$2:$F$7926,M$5,'SN04'!$D$2:$D$7926,$E39,'SN04'!$G$2:$G$7926,"*") -> 0 | N39: =countifs('SN04'!$F$2:$F$7926,N$5,'SN04'!$D$2:$D$7926,$E39,'SN04'!$G$2:$G$7926,"*") -> 0 | ... AF39: =countifs('SN04'!$F$2:$F$7926,AF$5,'SN04'!$D$2:$D$7926,$E39,'SN04'!$G$2:$G$7926,"*") -> 0
B40: 27 | C40: Hoàng Ngọc Huyền | D40: =sum(H40:AK40) -> 0 | E40: G026@gdsonline.tech | F40: SN04 | G40: =countifs('SN04'!$F$2:$F$7926,G$5,'SN04'!$D$2:$D$7926,$E40,'SN04'!$G$2:$G$7926,"*") -> 0 | H40: =countifs('SN04'!$F$2:$F$7926,H$5,'SN04'!$D$2:$D$7926,$E40,'SN04'!$G$2:$G$7926,"*") -> 0 | I40: =countifs('SN04'!$F$2:$F$7926,I$5,'SN04'!$D$2:$D$7926,$E40,'SN04'!$G$2:$G$7926,"*") -> 0 | J40: =countifs('SN04'!$F$2:$F$7926,J$5,'SN04'!$D$2:$D$7926,$E40,'SN04'!$G$2:$G$7926,"*") -> 0 | K40: =countifs('SN04'!$F$2:$F$7926,K$5,'SN04'!$D$2:$D$7926,$E40,'SN04'!$G$2:$G$7926,"*") -> 0 | L40: =countifs('SN04'!$F$2:$F$7926,L$5,'SN04'!$D$2:$D$7926,$E40,'SN04'!$G$2:$G$7926,"*") -> 0 | M40: =countifs('SN04'!$F$2:$F$7926,M$5,'SN04'!$D$2:$D$7926,$E40,'SN04'!$G$2:$G$7926,"*") -> 0 | N40: =countifs('SN04'!$F$2:$F$7926,N$5,'SN04'!$D$2:$D$7926,$E40,'SN04'!$G$2:$G$7926,"*") -> 0 | ... AF40: =countifs('SN04'!$F$2:$F$7926,AF$5,'SN04'!$D$2:$D$7926,$E40,'SN04'!$G$2:$G$7926,"*") -> 0
B41: 14 | C41: Nguyễn Quang Tuyên | D41: =sum(H41:AK41) -> 0 | E41: G014@gdsonline.tech | F41: SN04 | G41: =countifs('SN03'!$F$3:$F$2000,G$5,'SN03'!$D$3:$D$2000,$E41,'SN03'!$G$3:$G$2000,"*") -> 0 | H41: =countifs('SN03'!$F$3:$F$2000,H$5,'SN03'!$D$3:$D$2000,$E41,'SN03'!$G$3:$G$2000,"*") -> 0 | I41: =countifs('SN03'!$F$3:$F$2000,I$5,'SN03'!$D$3:$D$2000,$E41,'SN03'!$G$3:$G$2000,"*") -> 0 | J41: =countifs('SN03'!$F$3:$F$2000,J$5,'SN03'!$D$3:$D$2000,$E41,'SN03'!$G$3:$G$2000,"*") -> 0 | K41: =countifs('SN03'!$F$3:$F$2000,K$5,'SN03'!$D$3:$D$2000,$E41,'SN03'!$G$3:$G$2000,"*") -> 0 | L41: =countifs('SN03'!$F$3:$F$2000,L$5,'SN03'!$D$3:$D$2000,$E41,'SN03'!$G$3:$G$2000,"*") -> 0 | M41: =countifs('SN03'!$F$3:$F$2000,M$5,'SN03'!$D$3:$D$2000,$E41,'SN03'!$G$3:$G$2000,"*") -> 0 | N41: =countifs('SN03'!$F$3:$F$2000,N$5,'SN03'!$D$3:$D$2000,$E41,'SN03'!$G$3:$G$2000,"*") -> 0 | ... AF41: =countifs('SN03'!$F$3:$F$2000,AF$5,'SN03'!$D$3:$D$2000,$E41,'SN03'!$G$3:$G$2000,"*") -> 0
B42: 28 | C42: Trần Quang Huy | D42: =sum(H42:AK42) -> 0 | E42: G027@gdsonline.tech | F42: SN04
B43: 29 | C43: Đặng Trần Thịnh | D43: =sum(H43:AK43) -> 0 | E43: G028@gdsonline.tech | F43: Not assigned yet
B44: 30 | D44: =sum(H44:AK44) -> 0 | E44: G029@gdsonline.tech | F44: Not assigned yet
B45: 31 | D45: =sum(H45:AK45) -> 0 | E45: G030@gdsonline.tech | F45: Not assigned yet

Sheet SN02
A1: Its123!@#
B2: # | C2: Full Name | D2: User name | E2: Team ID | F2: Ngày | G2: UID | H2: Task Link | I2: Status | J2: Feedback (optional) | K2: # checklist | L2: decision | M2: trace_id
B3: =countif(G:G,G3) -> 1 | C3: Đỗ Mạnh Tùng | D3: G009@gdsonline.tech | E3: SN02 | F3: 27/12 | G3: a6fd26f4-5ebb-4c31-9867-6479e29546c0 | H3: https://webolmo-data-snorkel.allen.ai/20251219_snorkel_batch008__llm_navqa_onlinemind2web_websites__138 | I3: Submission | J3: Không thể qua được cookie để truy cập web | K3: 41 | L3: =iferror(VLOOKUP(M3,Evals!A:B,2,0),"No infirmation") -> No infirmation | M3: =MID(H3,39,99999) -> 20251219_snorkel_batch008__llm_navqa_onlinemind2web_websites__138
B4: =countif(G:G,G4) -> 1 | C4: Đỗ Mạnh Tùng | D4: G009@gdsonline.tech | E4: SN02 | F4: 27/12 | G4: 118a6dbe-494b-4d8f-8962-0835f9e299c9 | H4: https://webolmo-data-snorkel.allen.ai/20251219_snorkel_batch007__llm_navqa_onlinemind2web_websites__38 | I4: Submission | J4: Không có URL trong task extension | K4: 42 | L4: =iferror(VLOOKUP(M4,Evals!A:B,2,0),"No infirmation") -> No infirmation | M4: =MID(H4,39,99999) -> 20251219_snorkel_batch007__llm_navqa_onlinemind2web_websites__38
B5: =countif(G:G,G5) -> 1 | C5: Đỗ Mạnh Tùng | D5: G009@gdsonline.tech | E5: SN02 | F5: 27/12 | G5: 51438813-1346-4d5c-9ed4-d9472a2f5385 | H5: https://webolmo-data-snorkel.allen.ai/20251219_snorkel_batch002__llm_navqa_popular_websites__13 | I5: Submission | L5: =iferror(VLOOKUP(M5,Evals!A:B,2,0),"No infirmation") -> No infirmation | M5: =MID(H5,39,99999) -> 20251219_snorkel_batch002__llm_navqa_popular_websites__13
B6: =countif(G:G,G6) -> 1 | C6: Đỗ Mạnh Tùng | D6: G009@gdsonline.tech | E6: SN02 | F6: 27/12 | G6: 8e17bf82-e59b-43d6-8a2d-638b59c2a14c | H6: https://webolmo-data-snorkel.allen.ai/20251219_snorkel_batch006__llm_navqa_popular_websites__139 | I6: Submission | J6: Không thể thực hiện do khi search bị mở sang tab mới | K6: 42 | L6: =iferror(VLOOKUP(M6,Evals!A:B,2,0),"No infirmation") -> No infirmation | M6: =MID(H6,39,99999) -> 20251219_snorkel_batch006__llm_navqa_popular_websites__139
B7: =countif(G:G,G7) -> 1 | C7: Đỗ Mạnh Tùng | D7: G009@gdsonline.tech | E7: SN02 | F7: 27/12 | G7: 76ed0682-534d-4e1e-8eb5-82c17a4b4527 | H7: https://webolmo-data-snorkel.allen.ai/20251219_snorkel_batch010__llm_navqa_popular_websites__4 | I7: Submission | J7: Website phải xác nhận robot | K7: 41 | L7: =iferror(VLOOKUP(M7,Evals!A:B,2,0),"No infirmation") -> No infirmation | M7: =MID(H7,39,99999) -> 20251219_snorkel_batch010__llm_navqa_popular_websites__4
B8: =countif(G:G,G8) -> 1 | C8: Đỗ Mạnh Tùng | D8: G009@gdsonline.tech | E8: SN02 | F8: 27/12 | G8: 2c5a3f44-9665-457f-9fe6-d26a309ce070 | H8: https://webolmo-data-snorkel.allen.ai/20251219_snorkel_batch009__llm_navqa_popular_websites__67 | I8: Submission | L8: =iferror(VLOOKUP(M8,Evals!A:B,2,0),"No infirmation") -> No infirmation | M8: =MID(H8,39,99999) -> 20251219_snorkel_batch009__llm_navqa_popular_websites__67
B9: =countif(G:G,G9) -> 1 | C9: Đỗ Mạnh Tùng | D9: G009@gdsonline.tech | E9: SN02 | F9: 27/12 | G9: df2d5a2d-9e76-49f0-a339-4953b8d277e9 | H9: https://webolmo-data-snorkel.allen.ai/20251219_snorkel_batch010__llm_navqa_onlinemind2web_websites__131 | I9: Submission | L9: =iferror(VLOOKUP(M9,Evals!A:B,2,0),"No infirmation") -> No infirmation | M9: =MID(H9,39,99999) -> 20251219_snorkel_batch010__llm_navqa_onlinemind2web_websites__131
B10: =countif(G:G,G10) -> 1 | C10: Đỗ Mạnh Tùng | D10: G009@gdsonline.tech | E10: SN02 | F10: 27/12 | G10: 7ea34960-7d19-48b0-b7a0-ba42a968e633 | H10: https://webolmo-data-snorkel.allen.ai/20251121_snorkel_batch001__webvoyager_like__254 | I10: Submission | L10: =iferror(VLOOKUP(M10,Evals!A:B,2,0),"No infirmation") -> No infirmation | M10: =MID(H10,39,99999) -> 20251121_snorkel_batch001__webvoyager_like__254
B11: =countif(G:G,G11) -> 1 | C11: Đỗ Mạnh Tùng | D11: G009@gdsonline.tech | E11: SN02 | F11: 27/12 | G11: cb637057-a891-471f-9e4f-bc372ac0d8ac | H11: https://webolmo-data-snorkel.allen.ai/20251219_snorkel_batch006__llm_navqa_webvoyager_websites__42 | I11: Submission | L11: =iferror(VLOOKUP(M11,Evals!A:B,2,0),"No infirmation") -> No infirmation | M11: =MID(H11,39,99999) -> 20251219_snorkel_batch006__llm_navqa_webvoyager_websites__42
B12: =countif(G:G,G12) -> 1 | C12: Đỗ Mạnh Tùng | D12: G009@gdsonline.tech | E12: SN02 | F12: 27/12 | G12: 1de4f115-4086-4558-949a-88ae05bbcd56 | H12: https://webolmo-data-snorkel.allen.ai/20251121_snorkel_batch001__webvoyager_like__373 | I12: Submission | L12: =iferror(VLOOKUP(M12,Evals!A:B,2,0),"No infirmation") -> No infirmation | M12: =MID(H12,39,99999) -> 20251121_snorkel_batch001__webvoyager_like__373
B13: =countif(G:G,G13) -> 1 | C13: Đỗ Mạnh Tùng | D13: G009@gdsonline.tech | E13: SN02 | F13: 27/12 | G13: 525a18a0-d411-409a-a236-6145ea694bac | H13: https://webolmo-data-snorkel.allen.ai/20251219_snorkel_batch001__llm_navqa_popular_websites__86 | I13: Submission | L13: =iferror(VLOOKUP(M13,Evals!A:B,2,0),"No infirmation") -> No infirmation | M13: =MID(H13,39,99999) -> 20251219_snorkel_batch001__llm_navqa_popular_websites__86
B14: =countif(G:G,G14) -> 1 | C14: Đỗ Mạnh Tùng | D14: G009@gdsonline.tech | E14: SN02 | F14: 27/12 | G14: 4f08950e-da37-40c9-b8ca-ff8b2f1deede | H14: https://webolmo-data-snorkel.allen.ai/20251121_snorkel_batch001__webvoyager_like__385 | I14: Submission | L14: =iferror(VLOOKUP(M14,Evals!A:B,2,0),"No infirmation") -> No infirmation | M14: =MID(H14,39,99999) -> 20251121_snorkel_batch001__webvoyager_like__385
B15: =countif(G:G,G15) -> 1 | C15: Đỗ Mạnh Tùng | D15: G009@gdsonline.tech | E15: SN02 | F15: 27/12 | G15: 668dabf7-db3a-4637-944a-51ec23500ad6 | H15: https://webolmo-data-snorkel.allen.ai/20251219_snorkel_batch008__llm_navqa_onlinemind2web_websites__68 | I15: Submission | L15: =iferror(VLOOKUP(M15,Evals!A:B,2,0),"No infirmation") -> No infirmation | M15: =MID(H15,39,99999) -> 20251219_snorkel_batch008__llm_navqa_onlinemind2web_websites__68
B16: =countif(G:G,G16) -> 1 | C16: Đỗ Mạnh Tùng | D16: G009@gdsonline.tech | E16: SN02 | F16: 27/12 | G16: 8892eb0c-d668-4d75-b6ac-f17371cccb0b | H16: https://webolmo-data-snorkel.allen.ai/20251219_snorkel_batch001__llm_navqa_webvoyager_websites__30 | I16: Submission | J16: Yêu cầu chưa rõ, yêu cầu tìm kiếm trên map là chưa đúng | K16: 40 | L16: =iferror(VLOOKUP(M16,Evals!A:B,2,0),"No infirmation") -> No infirmation | M16: =MID(H16,39,99999) -> 20251219_snorkel_batch001__llm_navqa_webvoyager_websites__30
B17: =countif(G:G,G17) -> 1 | C17: Đỗ Mạnh Tùng | D17: G009@gdsonline.tech | E17: SN02 | F17: 27/12 | G17: 1cefbc26-471c-4414-84d9-51c4ebf151de | H17: https://webolmo-data-snorkel.allen.ai/20251219_snorkel_batch005__llm_navqa_onlinemind2web_websites__24 | I17: Submission | J17: Không có URL trong task extension | K17: 42 | L17: =iferror(VLOOKUP(M17,Evals!A:B,2,0),"No infirmation") -> No infirmation | M17: =MID(H17,39,99999) -> 20251219_snorkel_batch005__llm_navqa_onlinemind2web_websites__24
B18: =countif(G:G,G18) -> 1 | C18: Đỗ Mạnh Tùng | D18: G009@gdsonline.tech | E18: SN02 | F18: 27/12 | G18: 10121b89-49cd-40f5-a287-4f3f4e0dafb8 | H18: https://webolmo-data-snorkel.allen.ai/20251219_snorkel_batch002__llm_navqa_webvoyager_websites__50 | I18: Submission | L18: =iferror(VLOOKUP(M18,Evals!A:B,2,0),"No infirmation") -> No infirmation | M18: =MID(H18,39,99999) -> 20251219_snorkel_batch002__llm_navqa_webvoyager_websites__50
B19: =countif(G:G,G19) -> 1 | C19: Đỗ Mạnh Tùng | D19: G009@gdsonline.tech | E19: SN02 | F19: 27/12 | G19: 1783d104-cca7-4c9c-bfd2-18600e351e4b | H19: https://webolmo-data-snorkel.allen.ai/20251219_snorkel_batch003__llm_navqa_onlinemind2web_websites__11 | I19: Submission | L19: =iferror(VLOOKUP(M19,Evals!A:B,2,0),"No infirmation") -> No infirmation | M19: =MID(H19,39,99999) -> 20251219_snorkel_batch003__llm_navqa_onlinemind2web_websites__11
B20: =countif(G:G,G20) -> 1 | C20: Đỗ Mạnh Tùng | D20: G009@gdsonline.tech | E20: SN02 | F20: 27/12 | G20: 3abbfb49-18a1-451b-9f15-4f3db1e4bdd2 | H20: https://webolmo-data-snorkel.allen.ai/20251219_snorkel_batch009__llm_navqa_webvoyager_websites__83 | I20: Submission | J20: Không có URL trong task extension | K20: 42 | L20: =iferror(VLOOKUP(M20,Evals!A:B,2,0),"No infirmation") -> No infirmation | M20: =MID(H20,39,99999) -> 20251219_snorkel_batch009__llm_navqa_webvoyager_websites__83
B21: =countif(G:G,G21) -> 1 | C21: Đỗ Mạnh Tùng | D21: G009@gdsonline.tech | E21: SN02 | F21: 27/12 | G21: b46b3264-e938-4054-aaae-d157a137ec3c | H21: https://webolmo-data-snorkel.allen.ai/20251219_snorkel_batch004__llm_navqa_webvoyager_websites__97 | I21: Submission | L21: =iferror(VLOOKUP(M21,Evals!A:B,2,0),"No infirmation") -> No infirmation | M21: =MID(H21,39,99999) -> 20251219_snorkel_batch004__llm_navqa_webvoyager_websites__97
B22: =countif(G:G,G22) -> 1 | C22: Đỗ Mạnh Tùng | D22: G009@gdsonline.tech | E22: SN02 | F22: 27/12 | G22: 3409498a-2f50-4226-8ce8-33f212a82cf3 | H22: https://webolmo-data-snorkel.allen.ai/20251219_snorkel_batch004__llm_navqa_popular_websites__36 | I22: Submission | L22: =iferror(VLOOKUP(M22,Evals!A:B,2,0),"No infirmation") -> No infirmation | M22: =MID(H22,39,99999) -> 20251219_snorkel_batch004__llm_navqa_popular_websites__36
B23: =countif(G:G,G23) -> 1 | C23: Đỗ Mạnh Tùng | D23: G009@gdsonline.tech | E23: SN02 | F23: 27/12 | G23: d7897142-2d72-4ca1-86e0-819655f97ec2 | H23: https://webolmo-data-snorkel.allen.ai/20251219_snorkel_batch004__llm_navqa_webvoyager_websites__65 | I23: Submission | L23: =iferror(VLOOKUP(M23,Evals!A:B,2,0),"No infirmation") -> No infirmation | M23: =MID(H23,39,99999) -> 20251219_snorkel_batch004__llm_navqa_webvoyager_websites__65
B24: =countif(G:G,G24) -> 1 | C24: Đỗ Mạnh Tùng | D24: G009@gdsonline.tech | E24: SN02 | F24: 27/12 | G24: 53656b7f-1b10-4361-b70f-2300ec724fd1 | H24: https://webolmo-data-snorkel.allen.ai/20251219_snorkel_batch008__llm_navqa_onlinemind2web_websites__94 | I24: Submission | L24: =iferror(VLOOKUP(M24,Evals!A:B,2,0),"No infirmation") -> No infirmation | M24: =MID(H24,39,99999) -> 20251219_snorkel_batch008__llm_navqa_onlinemind2web_websites__94
B25: =countif(G:G,G25) -> 1 | C25: Đỗ Mạnh Tùng | D25: G009@gdsonline.tech | E25: SN02 | F25: 27/12 | G25: 09e6796a-551b-40fc-b1cc-8f58bc5d062e | H25: https://webolmo-data-snorkel.allen.ai/20251219_snorkel_batch004__llm_navqa_popular_websites__126 | I25: Submission | L25: =iferror(VLOOKUP(M25,Evals!A:B,2,0),"No infirmation") -> No infirmation | M25: =MID(H25,39,99999) -> 20251219_snorkel_batch004__llm_navqa_popular_websites__126
B26: =countif(G:G,G26) -> 1 | C26: Đỗ Mạnh Tùng | D26: G009@gdsonline.tech | E26: SN02 | F26: 27/12 | G26: 564a277f-e3fe-4286-a00a-81c097113b66 | H26: https://webolmo-data-snorkel.allen.ai/20251219_snorkel_batch010__llm_navqa_webvoyager_websites__14 | I26: Submission | L26: =iferror(VLOOKUP(M26,Evals!A:B,2,0),"No infirmation") -> No infirmation | M26: =MID(H26,39,99999) -> 20251219_snorkel_batch010__llm_navqa_webvoyager_websites__14
B27: =countif(G:G,G27) -> 1 | C27: Đỗ Mạnh Tùng | D27: G009@gdsonline.tech | E27: SN02 | F27: 27/12 | G27: ef9c6c71-01fe-4125-9466-ec01cce9ba46 | H27: https://webolmo-data-snorkel.allen.ai/20251219_snorkel_batch005__llm_navqa_onlinemind2web_websites__127 | I27: Submission | L27: =iferror(VLOOKUP(M27,Evals!A:B,2,0),"No infirmation") -> No infirmation | M27: =MID(H27,39,99999) -> 20251219_snorkel_batch005__llm_navqa_onlinemind2web_websites__127
B28: =countif(G:G,G28) -> 1 | C28: Đỗ Mạnh Tùng | D28: G009@gdsonline.tech | E28: SN02 | F28: 27/12 | G28: d9fbf3ab-e456-4540-aa1b-b84ea4ddcb17 | H28: https://webolmo-data-snorkel.allen.ai/20251219_snorkel_batch005__llm_navqa_popular_websites__42 | I28: Submission | L28: =iferror(VLOOKUP(M28,Evals!A:B,2,0),"No infirmation") -> No infirmation | M28: =MID(H28,39,99999) -> 20251219_snorkel_batch005__llm_navqa_popular_websites__42
B29: =countif(G:G,G29) -> 1 | C29: Đỗ Mạnh Tùng | D29: G009@gdsonline.tech | E29: SN02 | F29: 27/12 | G29: a4a5948d-f2a6-47d8-8c3c-1f0762b98b26 | H29: https://webolmo-data-snorkel.allen.ai/20251219_snorkel_batch010__llm_navqa_popular_websites__7 | I29: Submission | L29: =iferror(VLOOKUP(M29,Evals!A:B,2,0),"No infirmation") -> No infirmation | M29: =MID(H29,39,99999) -> 20251219_snorkel_batch010__llm_navqa_popular_websites__7
B30: =countif(G:G,G30) -> 1 | C30: Đỗ Mạnh Tùng | D30: G009@gdsonline.tech | E30: SN02 | F30: 27/12 | G30: d1c3f09a-0193-44c4-b5fe-91dddd0fa688 | H30: https://webolmo-data-snorkel.allen.ai/20251121_snorkel_batch001__webvoyager_like__299 | I30: Submission | L30: =iferror(VLOOKUP(M30,Evals!A:B,2,0),"No infirmation") -> No infirmation | M30: =MID(H30,39,99999) -> 20251121_snorkel_batch001__webvoyager_like__299
B31: =countif(G:G,G31) -> 1 | C31: Đỗ Mạnh Tùng | D31: G009@gdsonline.tech | E31: SN02 | F31: 27/12 | G31: bc40bf3e-8d2a-4d4a-bd57-2b3be60d7f69 | H31: https://webolmo-data-snorkel.allen.ai/20251219_snorkel_batch009__llm_navqa_popular_websites__18 | I31: Submission | L31: =iferror(VLOOKUP(M31,Evals!A:B,2,0),"No infirmation") -> No infirmation | M31: =MID(H31,39,99999) -> 20251219_snorkel_batch009__llm_navqa_popular_websites__18
B32: =countif(G:G,G32) -> 1 | C32: Đỗ Mạnh Tùng | D32: G009@gdsonline.tech | E32: SN02 | F32: 27/12 | G32: 87a75ec3-9c3a-4f23-b2a7-4192b38153e1 | H32: https://webolmo-data-snorkel.allen.ai/20251219_snorkel_batch009__llm_navqa_popular_websites__66 | I32: Submission | L32: =iferror(VLOOKUP(M32,Evals!A:B,2,0),"No infirmation") -> No infirmation | M32: =MID(H32,39,99999) -> 20251219_snorkel_batch009__llm_navqa_popular_websites__66
... B61: =countif(G:G,G61) -> 1 | C61: Đỗ Mạnh Tùng | D61: G009@gdsonline.tech | E61: SN02 | F61: 27/12 | G61: 6b8ca02d-ad92-41ed-aa17-92aee123eba1 | H61: https://webolmo-data-snorkel.allen.ai/20251219_snorkel_batch008__llm_navqa_webvoyager_websites__87 | I61: Submission | L61: =iferror(VLOOKUP(M61,Evals!A:B,2,0),"No infirmation") -> No infirmation | M61: =MID(H61,39,99999) -> 20251219_snorkel_batch008__llm_navqa_webvoyager_websites__87
B62: =countif(G:G,G62) -> 1 | C62: Đỗ Mạnh Tùng | D62: G009@gdsonline.tech | E62: SN02 | F62: 27/12 | G62: 8016db02-2bf0-40db-8bab-9545fc01a3e2 | H62: https://webolmo-data-snorkel.allen.ai/20251219_snorkel_batch006__llm_navqa_popular_websites__67 | I62: Submission | J62: Function search của website không hoạt động | K62: 40 | L62: =iferror(VLOOKUP(M62,Evals!A:B,2,0),"No infirmation") -> No infirmation | M62: =MID(H62,39,99999) -> 20251219_snorkel_batch006__llm_navqa_popular_websites__67
B63: =countif(G:G,G63) -> 1 | C63: Đỗ Mạnh Tùng | D63: G009@gdsonline.tech | E63: SN02 | F63: 27/12 | G63: 133605e0-0b51-40b7-a2d8-39b96fa9ff11 | H63: https://webolmo-data-snorkel.allen.ai/20251219_snorkel_batch010__llm_navqa_webvoyager_websites__82 | I63: Submission | J63: Detail không xem được | K63: 40 | L63: =iferror(VLOOKUP(M63,Evals!A:B,2,0),"No infirmation") -> No infirmation | M63: =MID(H63,39,99999) -> 20251219_snorkel_batch010__llm_navqa_webvoyager_websites__82
